<?xml version="1.0"?>
<robot xmlns:xacro="http://www.ros.org/wiki/xacro" name="my_robot">

  <!-- ===================== -->
  <!-- Robot parameters -->
  <!-- ===================== -->

  <xacro:property name="base_length" value="0.56"/>
  <xacro:property name="base_width" value="0.34"/>
  <xacro:property name="base_height" value="0.11"/>

  <xacro:property name="wheel_radius" value="0.08"/>
  <xacro:property name="wheel_width" value="0.045"/>

  <xacro:property name="drive_wheel_x_offset" value="-0.16"/>
  <xacro:property name="wheel_y_offset" value="0.20"/>
  <xacro:property name="wheel_z_offset" value="-0.025"/>

  <xacro:property name="caster_x_offset" value="0.23"/>
  <xacro:property name="caster_radius" value="0.045"/>
  <xacro:property name="caster_width" value="0.025"/>
  <xacro:property name="caster_z_offset" value="-0.06"/>

  <xacro:property name="laser_radius" value="0.06"/>
  <xacro:property name="laser_height" value="0.04"/>

  <!-- ===================== -->
  <!-- Materials -->
  <!-- ===================== -->

  <material name="blue">
    <color rgba="0.1 0.3 0.8 1.0"/>
  </material>

  <material name="black">
    <color rgba="0.02 0.02 0.02 1.0"/>
  </material>

  <material name="gray">
    <color rgba="0.45 0.45 0.45 1.0"/>
  </material>

  <material name="red">
    <color rgba="0.9 0.1 0.1 1.0"/>
  </material>

  <!-- ===================== -->
  <!-- Base footprint -->
  <!-- ===================== -->

  <link name="base_footprint"/>

  <joint name="base_joint" type="fixed">
    <parent link="base_footprint"/>
    <child link="base_link"/>
    <origin xyz="0 0 0.105" rpy="0 0 0"/>
  </joint>

  <!-- ===================== -->
  <!-- Base link -->
  <!-- ===================== -->

  <link name="base_link">
    <visual>
      <geometry>
        <box size="${base_length} ${base_width} ${base_height}"/>
      </geometry>
      <material name="blue"/>
    </visual>

    <collision>
      <geometry>
        <box size="${base_length} ${base_width} ${base_height}"/>
      </geometry>
    </collision>

    <inertial>
      <mass value="8.0"/>
      <inertia
        ixx="0.085" ixy="0.0" ixz="0.0"
        iyy="0.217" iyz="0.0"
        izz="0.286"/>
    </inertial>
  </link>

  <!-- ===================== -->
  <!-- Wheel macro -->
  <!-- ===================== -->

  <xacro:macro name="wheel" params="name x y">
    <joint name="${name}_joint" type="continuous">
      <parent link="base_link"/>
      <child link="${name}_link"/>
      <origin xyz="${x} ${y} ${wheel_z_offset}" rpy="${-pi/2} 0 0"/>
      <axis xyz="0 0 1"/>
    </joint>

    <link name="${name}_link">
      <visual>
        <geometry>
          <cylinder radius="${wheel_radius}" length="${wheel_width}"/>
        </geometry>
        <material name="black"/>
      </visual>

      <collision>
        <geometry>
          <cylinder radius="${wheel_radius}" length="${wheel_width}"/>
        </geometry>
      </collision>

      <inertial>
        <mass value="0.8"/>
        <inertia
          ixx="0.002" ixy="0.0" ixz="0.0"
          iyy="0.002" iyz="0.0"
          izz="0.002"/>
      </inertial>
    </link>
  </xacro:macro>

  <!-- ===================== -->
  <!-- Two differential-drive wheels -->
  <!-- ===================== -->

  <xacro:wheel name="left_wheel"  x="${drive_wheel_x_offset}" y="${wheel_y_offset}"/>
  <xacro:wheel name="right_wheel" x="${drive_wheel_x_offset}" y="${-wheel_y_offset}"/>

  <!-- ===================== -->
  <!-- Passive caster support -->
  <!-- ===================== -->

  <joint name="caster_swivel_joint" type="continuous">
    <parent link="base_link"/>
    <child link="caster_swivel_link"/>
    <origin xyz="${caster_x_offset} 0 ${caster_z_offset}" rpy="0 0 0"/>
    <axis xyz="0 0 1"/>
  </joint>

  <link name="caster_swivel_link">
    <visual>
      <geometry>
        <sphere radius="0.015"/>
      </geometry>
      <material name="gray"/>
    </visual>

    <inertial>
      <mass value="0.05"/>
      <inertia
        ixx="0.00002" ixy="0.0" ixz="0.0"
        iyy="0.00002" iyz="0.0"
        izz="0.00002"/>
    </inertial>
  </link>

  <joint name="caster_wheel_joint" type="continuous">
    <parent link="caster_swivel_link"/>
    <child link="caster_wheel_link"/>
    <origin xyz="0 0 0" rpy="${pi/2} 0 0"/>
    <axis xyz="0 0 1"/>
  </joint>

  <link name="caster_wheel_link">
    <visual>
      <geometry>
        <cylinder radius="${caster_radius}" length="${caster_width}"/>
      </geometry>
      <material name="gray"/>
    </visual>

    <collision>
      <geometry>
        <cylinder radius="${caster_radius}" length="${caster_width}"/>
      </geometry>
    </collision>

    <inertial>
      <mass value="0.15"/>
      <inertia
        ixx="0.0001" ixy="0.0" ixz="0.0"
        iyy="0.0001" iyz="0.0"
        izz="0.0001"/>
    </inertial>
  </link>

  <!-- ===================== -->
  <!-- Laser lidar -->
  <!-- ===================== -->

  <joint name="laser_joint" type="fixed">
    <parent link="base_link"/>
    <child link="laser_link"/>
    <origin xyz="0.14 0 0.08" rpy="0 0 0"/>
  </joint>

  <link name="laser_link">
    <visual>
      <geometry>
        <cylinder radius="${laser_radius}" length="${laser_height}"/>
      </geometry>
      <material name="red"/>
    </visual>

    <collision>
      <geometry>
        <cylinder radius="${laser_radius}" length="${laser_height}"/>
      </geometry>
    </collision>

    <inertial>
      <mass value="0.2"/>
      <inertia
        ixx="0.0005" ixy="0.0" ixz="0.0"
        iyy="0.0005" iyz="0.0"
        izz="0.0005"/>
    </inertial>
  </link>

</robot>
