<?xml version="1.0"?>
<robot xmlns:xacro="http://www.ros.org/wiki/xacro" name="my_robot">

  <xacro:property name="base_length" value="0.60"/>
  <xacro:property name="base_width" value="0.40"/>
  <xacro:property name="base_height" value="0.15"/>

  <xacro:property name="wheel_radius" value="0.08"/>
  <xacro:property name="wheel_width" value="0.04"/>
  <xacro:property name="wheel_x_offset" value="0.21"/>
  <xacro:property name="wheel_y_offset" value="0.23"/>
  <xacro:property name="wheel_z_offset" value="-0.04"/>

  <xacro:property name="laser_radius" value="0.07"/>
  <xacro:property name="laser_height" value="0.05"/>

  <material name="blue">
    <color rgba="0.1 0.3 0.8 1.0"/>
  </material>

  <material name="black">
    <color rgba="0.02 0.02 0.02 1.0"/>
  </material>

  <material name="red">
    <color rgba="0.9 0.1 0.1 1.0"/>
  </material>

  <link name="base_footprint"/>

  <joint name="base_joint" type="fixed">
    <parent link="base_footprint"/>
    <child link="base_link"/>
    <origin xyz="0 0 0.12" rpy="0 0 0"/>
  </joint>

  <link name="base_link">
    <visual>
      <geometry>
        <box size="${base_length} ${base_width} ${base_height}"/>
      </geometry>
      <material name="blue"/>
    </visual>

    <collision>
      <geometry>
        <box size="${base_length} ${base_width} ${base_height}"/>
      </geometry>
    </collision>

    <inertial>
      <mass value="8.0"/>
      <inertia
        ixx="0.12" ixy="0.0" ixz="0.0"
        iyy="0.25" iyz="0.0"
        izz="0.30"/>
    </inertial>
  </link>

  <xacro:macro name="wheel" params="name x y">
    <joint name="${name}_joint" type="continuous">
      <parent link="base_link"/>
      <child link="${name}_link"/>
      <origin xyz="${x} ${y} ${wheel_z_offset}" rpy="${pi/2} 0 0"/>
      <axis xyz="0 0 -1"/>
    </joint>

    <link name="${name}_link">
      <visual>
        <geometry>
          <cylinder radius="${wheel_radius}" length="${wheel_width}"/>
        </geometry>
        <material name="black"/>
      </visual>

      <collision>
        <geometry>
          <cylinder radius="${wheel_radius}" length="${wheel_width}"/>
        </geometry>
      </collision>

      <inertial>
        <mass value="0.8"/>
        <inertia
          ixx="0.002" ixy="0.0" ixz="0.0"
          iyy="0.002" iyz="0.0"
          izz="0.002"/>
      </inertial>
    </link>
  </xacro:macro>

  <xacro:wheel name="left_front_wheel"  x="${wheel_x_offset}"  y="${wheel_y_offset}"/>
  <xacro:wheel name="left_rear_wheel"   x="${-wheel_x_offset}" y="${wheel_y_offset}"/>
  <xacro:wheel name="right_front_wheel" x="${wheel_x_offset}"  y="${-wheel_y_offset}"/>
  <xacro:wheel name="right_rear_wheel"  x="${-wheel_x_offset}" y="${-wheel_y_offset}"/>

  <joint name="laser_joint" type="fixed">
    <parent link="base_link"/>
    <child link="laser_link"/>
    <origin xyz="0.20 0 0.10" rpy="0 0 0"/>
  </joint>

  <link name="laser_link">
    <visual>
      <geometry>
        <cylinder radius="${laser_radius}" length="${laser_height}"/>
      </geometry>
      <material name="red"/>
    </visual>

    <collision>
      <geometry>
        <cylinder radius="${laser_radius}" length="${laser_height}"/>
      </geometry>
    </collision>

    <inertial>
      <mass value="0.2"/>
      <inertia
        ixx="0.0005" ixy="0.0" ixz="0.0"
        iyy="0.0005" iyz="0.0"
        izz="0.0005"/>
    </inertial>
  </link>

</robot>
