<?xml version="1.0"?>
<robot xmlns:xacro="http://www.ros.org/wiki/xacro" name="my_robot">

  <!-- ===================== -->
  <!-- Robot parameters -->
  <!-- ===================== -->

  <xacro:property name="base_length" value="0.60"/>
  <xacro:property name="base_width" value="0.40"/>
  <xacro:property name="base_height" value="0.15"/>

  <xacro:property name="wheel_radius" value="0.08"/>
  <xacro:property name="wheel_width" value="0.04"/>

  <xacro:property name="wheel_x_offset" value="0.21"/>
  <xacro:property name="wheel_y_offset" value="0.23"/>
  <xacro:property name="wheel_z_offset" value="-0.045"/>

  <xacro:property name="laser_radius" value="0.07"/>
  <xacro:property name="laser_height" value="0.05"/>

  <!-- ===================== -->
  <!-- Materials -->
  <!-- ===================== -->

  <material name="blue">
    <color rgba="0.1 0.3 0.8 1.0"/>
  </material>

  <material name="black">
    <color rgba="0.02 0.02 0.02 1.0"/>
  </material>

  <material name="red">
    <color rgba="0.9 0.1 0.1 1.0"/>
  </material>

  <!-- ===================== -->
  <!-- Base footprint -->
  <!-- ===================== -->

  <link name="base_footprint"/>

  <joint name="base_joint" type="fixed">
    <parent link="base_footprint"/>
    <child link="base_link"/>
    <origin xyz="0 0 0.12" rpy="0 0 0"/>
  </joint>

  <!-- ===================== -->
  <!-- Base link -->
  <!-- ===================== -->

  <link name="base_link">
    <visual>
      <geometry>
        <box size="${base_length} ${base_width} ${base_height}"/>
      </geometry>
      <material name="blue"/>
    </visual>

    <collision>
      <geometry>
        <box size="${base_length} ${base_width} ${base_height}"/>
      </geometry>
    </collision>

    <inertial>
      <mass value="8.0"/>
      <inertia
        ixx="0.12" ixy="0.0" ixz="0.0"
        iyy="0.25" iyz="0.0"
        izz="0.30"/>
    </inertial>
  </link>

  <!-- ===================== -->
  <!-- Wheel macro -->
  <!-- ===================== -->

  <xacro:macro name="wheel" params="name x y">
    <joint name="${name}_joint" type="continuous">
      <parent link="base_link"/>
      <child link="${name}_link"/>
      <origin xyz="${x} ${y} ${wheel_z_offset}" rpy="${pi/2} 0 0"/>
      <axis xyz="0 0 1"/>
    </joint>

    <link name="${name}_link">
      <visual>
        <geometry>
          <cylinder radius="${wheel_radius}" length="${wheel_width}"/>
        </geometry>
        <material name="black"/>
      </visual>

      <collision>
        <geometry>
          <cylinder radius="${wheel_radius}" length="${wheel_width}"/>
        </geometry>
      </collision>

      <inertial>
        <mass value="0.8"/>
        <inertia
          ixx="0.002" ixy="0.0" ixz="0.0"
          iyy="0.002" iyz="0.0"
          izz="0.002"/>
      </inertial>
    </link>
  </xacro:macro>

  <!-- ===================== -->
  <!-- Four wheels -->
  <!-- ===================== -->

  <xacro:wheel name="left_front_wheel"  x="${wheel_x_offset}"  y="${wheel_y_offset}"/>
  <xacro:wheel name="left_rear_wheel"   x="${-wheel_x_offset}" y="${wheel_y_offset}"/>
  <xacro:wheel name="right_front_wheel" x="${wheel_x_offset}"  y="${-wheel_y_offset}"/>
  <xacro:wheel name="right_rear_wheel"  x="${-wheel_x_offset}" y="${-wheel_y_offset}"/>

  <!-- ===================== -->
  <!-- Laser lidar -->
  <!-- ===================== -->

  <joint name="laser_joint" type="fixed">
    <parent link="base_link"/>
    <child link="laser_link"/>
    <origin xyz="0.20 0 0.13" rpy="0 0 0"/>
  </joint>

  <link name="laser_link">
    <visual>
      <geometry>
        <cylinder radius="${laser_radius}" length="${laser_height}"/>
      </geometry>
      <material name="red"/>
    </visual>

    <collision>
      <geometry>
        <cylinder radius="${laser_radius}" length="${laser_height}"/>
      </geometry>
    </collision>

    <inertial>
      <mass value="0.2"/>
      <inertia
        ixx="0.0005" ixy="0.0" ixz="0.0"
        iyy="0.0005" iyz="0.0"
        izz="0.0005"/>
    </inertial>
  </link>

  <!-- ===================== -->
  <!-- Gazebo diff drive -->
  <!-- ===================== -->

  <gazebo>
    <plugin
      filename="gz-sim-diff-drive-system"
      name="gz::sim::systems::DiffDrive">

      <left_joint>left_front_wheel_joint</left_joint>
      <left_joint>left_rear_wheel_joint</left_joint>

      <right_joint>right_front_wheel_joint</right_joint>
      <right_joint>right_rear_wheel_joint</right_joint>

      <wheel_separation>${2 * wheel_y_offset}</wheel_separation>
      <wheel_radius>${wheel_radius}</wheel_radius>

      <odom_publish_frequency>50</odom_publish_frequency>
      <max_velocity>1.0</max_velocity>
      <max_acceleration>0.8</max_acceleration>
      <max_jerk>2.0</max_jerk>

      <topic>/cmd_vel</topic>
      <odom_topic>/odom</odom_topic>
      <frame_id>odom</frame_id>
      <child_frame_id>base_footprint</child_frame_id>

    </plugin>
  </gazebo>

  <!-- Keep wheel contact predictable in simulation. Low side friction helps a
       skid-steer/four-wheel diff robot turn without dragging odometry away. -->
  <gazebo reference="left_front_wheel_link">
    <mu1>1.0</mu1>
    <mu2>0.2</mu2>
  </gazebo>

  <gazebo reference="left_rear_wheel_link">
    <mu1>1.0</mu1>
    <mu2>0.2</mu2>
  </gazebo>

  <gazebo reference="right_front_wheel_link">
    <mu1>1.0</mu1>
    <mu2>0.2</mu2>
  </gazebo>

  <gazebo reference="right_rear_wheel_link">
    <mu1>1.0</mu1>
    <mu2>0.2</mu2>
  </gazebo>
  
  <!-- ===================== -->
  <!-- Gazebo lidar sensor -->
  <!-- ===================== -->

  <gazebo reference="base_link">
    <sensor name="laser_sensor" type="gpu_lidar">
      <pose>0.20 0 0.13 0 0 0</pose>
      <topic>/scan</topic>
      <update_rate>10</update_rate>
      <gz_frame_id>laser_link</gz_frame_id>
      
      <ray>
        <scan>
          <horizontal>
            <samples>360</samples>
            <resolution>1</resolution>
            <min_angle>-3.14159</min_angle>
            <max_angle>3.14159</max_angle>
          </horizontal>
        </scan>
        <range>
          <min>0.12</min>
          <max>10.0</max>
          <resolution>0.01</resolution>
        </range>
        <noise>
          <type>gaussian</type>
          <mean>0.0</mean>
          <stddev>0.01</stddev>
        </noise>
      </ray>
      <always_on>true</always_on>
      <visualize>true</visualize>
    </sensor>
  </gazebo>
  
</robot>
